[2024-04-26T16:48:12Z] DEBUG    - Logging set up successfully
[2024-04-26T16:48:12Z] DEBUG    - Running validate: Namespace(version=False, subparser_name='validate', command=<function validate at 0x71ddd14a2c20>, verbose=0)
[2024-04-26T16:48:12Z] DEBUG    - Root directory: /home/jg/git/labs/cfn-ec2-autoscale
[2024-04-26T16:48:12Z] DEBUG    - Loading project file '/home/jg/git/labs/cfn-ec2-autoscale/.rpdk-config'
[2024-04-26T16:48:12Z] DEBUG    - Project file /home/jg/git/labs/cfn-ec2-autoscale/.rpdk-config not found. Have you run 'init' or in a wrong directory?
Traceback (most recent call last):
  File "/home/jg/.local/lib/python3.10/site-packages/rpdk/core/project.py", line 551, in load
    self.load_settings()
  File "/home/jg/.local/lib/python3.10/site-packages/rpdk/core/project.py", line 218, in load_settings
    with self.settings_path.open("r", encoding="utf-8") as f:
  File "/usr/lib/python3.10/pathlib.py", line 1119, in open
    return self._accessor.open(self, mode, buffering, encoding, errors,
FileNotFoundError: [Errno 2] No such file or directory: '/home/jg/git/labs/cfn-ec2-autoscale/.rpdk-config'
[2024-04-26T16:48:12Z] DEBUG    - Caught exit recommendation
Traceback (most recent call last):
  File "/home/jg/.local/lib/python3.10/site-packages/rpdk/core/project.py", line 551, in load
    self.load_settings()
  File "/home/jg/.local/lib/python3.10/site-packages/rpdk/core/project.py", line 218, in load_settings
    with self.settings_path.open("r", encoding="utf-8") as f:
  File "/usr/lib/python3.10/pathlib.py", line 1119, in open
    return self._accessor.open(self, mode, buffering, encoding, errors,
FileNotFoundError: [Errno 2] No such file or directory: '/home/jg/git/labs/cfn-ec2-autoscale/.rpdk-config'

The above exception was the direct cause of the following exception:

Traceback (most recent call last):
  File "/home/jg/.local/lib/python3.10/site-packages/rpdk/core/cli.py", line 105, in main
    args.command(args)
  File "/home/jg/.local/lib/python3.10/site-packages/rpdk/core/validate.py", line 14, in validate
    project.load()
  File "/home/jg/.local/lib/python3.10/site-packages/rpdk/core/project.py", line 553, in load
    self._raise_invalid_project(
  File "/home/jg/.local/lib/python3.10/site-packages/rpdk/core/project.py", line 213, in _raise_invalid_project
    raise InvalidProjectError(msg) from e
rpdk.core.exceptions.InvalidProjectError: Project file /home/jg/git/labs/cfn-ec2-autoscale/.rpdk-config not found. Have you run 'init' or in a wrong directory?
[2024-04-26T16:48:12Z] CRITICAL - Project file /home/jg/git/labs/cfn-ec2-autoscale/.rpdk-config not found. Have you run 'init' or in a wrong directory?
[2024-04-26T16:48:20Z] DEBUG    - Logging set up successfully
[2024-04-26T16:48:20Z] DEBUG    - Running None: Namespace(version=False, subparser_name=None, command=<function init at 0x799cc177b010>, verbose=0, force=False, type_name=None, artifact_type=None, endpoint_url=None, region=None, target_schemas=[], profile=None)
[2024-04-26T16:48:20Z] DEBUG    - Root directory: /home/jg/git/labs/cfn-ec2-autoscale
[2024-04-26T16:48:20Z] WARNING  - Initializing new project
[2024-04-26T16:48:20Z] DEBUG    - Loading project file '/home/jg/git/labs/cfn-ec2-autoscale/.rpdk-config'
